error


terminal
(venv) PS C:\americo\API\TaskGenie_flask> flask run
 * Serving Flask app 'run:app'
 * Debug mode: off
WARNING: This is a development server. Do not use it in a production deployment. Use a production WSGI server instead.
 * Running on http://127.0.0.1:5000
Press CTRL+C to quit
[2025-06-13 14:20:15,197] ERROR in app: Exception on / [GET]
Traceback (most recent call last):
  File "C:\americo\API\TaskGenie_flask\venv\Lib\site-packages\flask\app.py", line 917, in full_dispatch_request
    rv = self.dispatch_request()
         ^^^^^^^^^^^^^^^^^^^^^^^
  File "C:\americo\API\TaskGenie_flask\venv\Lib\site-packages\flask\app.py", line 891, in dispatch_request
    self.raise_routing_exception(req)
  File "C:\americo\API\TaskGenie_flask\venv\Lib\site-packages\flask\app.py", line 500, in raise_routing_exception
    raise request.routing_exception  # type: ignore[misc]
    ^^^^^^^^^^^^^^^^^^^^^^^^^^^^^^^
  File "C:\americo\API\TaskGenie_flask\venv\Lib\site-packages\flask\ctx.py", line 362, in match_request
    result = self.url_adapter.match(return_rule=True)  # type: ignore
             ^^^^^^^^^^^^^^^^^^^^^^^^^^^^^^^^^^^^^^^^
  File "C:\americo\API\TaskGenie_flask\venv\Lib\site-packages\werkzeug\routing\map.py", line 629, in match
    raise NotFound() from None
werkzeug.exceptions.NotFound: 404 Not Found: The requested URL was not found on the server. If you entered the URL manually please check your spelling and try again.

During handling of the above exception, another exception occurred:

Traceback (most recent call last):
  File "C:\americo\API\TaskGenie_flask\venv\Lib\site-packages\flask\app.py", line 1511, in wsgi_app
    response = self.full_dispatch_request()
               ^^^^^^^^^^^^^^^^^^^^^^^^^^^^
  File "C:\americo\API\TaskGenie_flask\venv\Lib\site-packages\flask\app.py", line 919, in full_dispatch_request
    rv = self.handle_user_exception(e)
         ^^^^^^^^^^^^^^^^^^^^^^^^^^^^^
  File "C:\americo\API\TaskGenie_flask\venv\Lib\site-packages\flask\app.py", line 802, in handle_user_exception
    return self.handle_http_exception(e)
           ^^^^^^^^^^^^^^^^^^^^^^^^^^^^^
  File "C:\americo\API\TaskGenie_flask\venv\Lib\site-packages\flask\app.py", line 777, in handle_http_exception
    return self.ensure_sync(handler)(e)  # type: ignore[no-any-return]
           ^^^^^^^^^^^^^^^^^^^^^^^^^^^^
  File "C:\americo\API\TaskGenie_flask\app\__init__.py", line 83, in not_found
    return render_template("errores.html", mensaje="Página no encontrada"), 404
           ^^^^^^^^^^^^^^^^^^^^^^^^^^^^^^^^^^^^^^^^^^^^^^^^^^^^^^^^^^^^^^^
  File "C:\americo\API\TaskGenie_flask\venv\Lib\site-packages\flask\templating.py", line 150, in render_template
    return _render(app, template, context)
           ^^^^^^^^^^^^^^^^^^^^^^^^^^^^^^^
  File "C:\americo\API\TaskGenie_flask\venv\Lib\site-packages\flask\templating.py", line 127, in _render
    app.update_template_context(context)
  File "C:\americo\API\TaskGenie_flask\venv\Lib\site-packages\flask\app.py", line 530, in update_template_context
    context.update(self.ensure_sync(func)())
                   ^^^^^^^^^^^^^^^^^^^^^^^^
  File "C:\americo\API\TaskGenie_flask\venv\Lib\site-packages\flask_login\utils.py", line 405, in _user_context_processor
    return dict(current_user=_get_user())
                             ^^^^^^^^^^^
  File "C:\americo\API\TaskGenie_flask\venv\Lib\site-packages\flask_login\utils.py", line 370, in _get_user
    current_app.login_manager._load_user()
  File "C:\americo\API\TaskGenie_flask\venv\Lib\site-packages\flask_login\login_manager.py", line 347, in _load_user
    raise Exception(
Exception: Missing user_loader or request_loader. Refer to http://flask-login.readthedocs.io/#how-it-works for more info.
127.0.0.1 - - [13/Jun/2025 14:20:15] "GET / HTTP/1.1" 500 -
[2025-06-13 14:20:15,284] ERROR in app: Exception on /favicon.ico [GET]
Traceback (most recent call last):
  File "C:\americo\API\TaskGenie_flask\venv\Lib\site-packages\flask\app.py", line 917, in full_dispatch_request
    rv = self.dispatch_request()
         ^^^^^^^^^^^^^^^^^^^^^^^
  File "C:\americo\API\TaskGenie_flask\venv\Lib\site-packages\flask\app.py", line 891, in dispatch_request
    self.raise_routing_exception(req)
  File "C:\americo\API\TaskGenie_flask\venv\Lib\site-packages\flask\app.py", line 500, in raise_routing_exception
    raise request.routing_exception  # type: ignore[misc]
    ^^^^^^^^^^^^^^^^^^^^^^^^^^^^^^^
  File "C:\americo\API\TaskGenie_flask\venv\Lib\site-packages\flask\ctx.py", line 362, in match_request
    result = self.url_adapter.match(return_rule=True)  # type: ignore
             ^^^^^^^^^^^^^^^^^^^^^^^^^^^^^^^^^^^^^^^^
  File "C:\americo\API\TaskGenie_flask\venv\Lib\site-packages\werkzeug\routing\map.py", line 629, in match
    raise NotFound() from None
werkzeug.exceptions.NotFound: 404 Not Found: The requested URL was not found on the server. If you entered the URL manually please check your spelling and try again.

During handling of the above exception, another exception occurred:

Traceback (most recent call last):
  File "C:\americo\API\TaskGenie_flask\venv\Lib\site-packages\flask\app.py", line 1511, in wsgi_app
    response = self.full_dispatch_request()
               ^^^^^^^^^^^^^^^^^^^^^^^^^^^^
  File "C:\americo\API\TaskGenie_flask\venv\Lib\site-packages\flask\app.py", line 919, in full_dispatch_request
    rv = self.handle_user_exception(e)
         ^^^^^^^^^^^^^^^^^^^^^^^^^^^^^
  File "C:\americo\API\TaskGenie_flask\venv\Lib\site-packages\flask\app.py", line 802, in handle_user_exception
    return self.handle_http_exception(e)
           ^^^^^^^^^^^^^^^^^^^^^^^^^^^^^
  File "C:\americo\API\TaskGenie_flask\venv\Lib\site-packages\flask\app.py", line 777, in handle_http_exception
    return self.ensure_sync(handler)(e)  # type: ignore[no-any-return]
           ^^^^^^^^^^^^^^^^^^^^^^^^^^^^
  File "C:\americo\API\TaskGenie_flask\app\__init__.py", line 83, in not_found
    return render_template("errores.html", mensaje="Página no encontrada"), 404
           ^^^^^^^^^^^^^^^^^^^^^^^^^^^^^^^^^^^^^^^^^^^^^^^^^^^^^^^^^^^^^^^
  File "C:\americo\API\TaskGenie_flask\venv\Lib\site-packages\flask\templating.py", line 150, in render_template
    return _render(app, template, context)
           ^^^^^^^^^^^^^^^^^^^^^^^^^^^^^^^
  File "C:\americo\API\TaskGenie_flask\venv\Lib\site-packages\flask\templating.py", line 127, in _render
    app.update_template_context(context)
  File "C:\americo\API\TaskGenie_flask\venv\Lib\site-packages\flask\app.py", line 530, in update_template_context
    context.update(self.ensure_sync(func)())
                   ^^^^^^^^^^^^^^^^^^^^^^^^
  File "C:\americo\API\TaskGenie_flask\venv\Lib\site-packages\flask_login\utils.py", line 405, in _user_context_processor
    return dict(current_user=_get_user())
                             ^^^^^^^^^^^
  File "C:\americo\API\TaskGenie_flask\venv\Lib\site-packages\flask_login\utils.py", line 370, in _get_user
    current_app.login_manager._load_user()
  File "C:\americo\API\TaskGenie_flask\venv\Lib\site-packages\flask_login\login_manager.py", line 347, in _load_user
    raise Exception(
Exception: Missing user_loader or request_loader. Refer to http://flask-login.readthedocs.io/#how-it-works for more info.
127.0.0.1 - - [13/Jun/2025 14:20:15] "GET /favicon.ico HTTP/1.1" 500 -
[2025-06-13 14:20:21,189] ERROR in app: Exception on /.well-known/appspecific/com.chrome.devtools.json [GET]
Traceback (most recent call last):
  File "C:\americo\API\TaskGenie_flask\venv\Lib\site-packages\flask\app.py", line 917, in full_dispatch_request
    rv = self.dispatch_request()
         ^^^^^^^^^^^^^^^^^^^^^^^
  File "C:\americo\API\TaskGenie_flask\venv\Lib\site-packages\flask\app.py", line 891, in dispatch_request
    self.raise_routing_exception(req)
  File "C:\americo\API\TaskGenie_flask\venv\Lib\site-packages\flask\app.py", line 500, in raise_routing_exception
    raise request.routing_exception  # type: ignore[misc]
    ^^^^^^^^^^^^^^^^^^^^^^^^^^^^^^^
  File "C:\americo\API\TaskGenie_flask\venv\Lib\site-packages\flask\ctx.py", line 362, in match_request
    result = self.url_adapter.match(return_rule=True)  # type: ignore
             ^^^^^^^^^^^^^^^^^^^^^^^^^^^^^^^^^^^^^^^^
  File "C:\americo\API\TaskGenie_flask\venv\Lib\site-packages\werkzeug\routing\map.py", line 629, in match
    raise NotFound() from None
werkzeug.exceptions.NotFound: 404 Not Found: The requested URL was not found on the server. If you entered the URL manually please check your spelling and try again.

During handling of the above exception, another exception occurred:

Traceback (most recent call last):
  File "C:\americo\API\TaskGenie_flask\venv\Lib\site-packages\flask\app.py", line 1511, in wsgi_app
    response = self.full_dispatch_request()
               ^^^^^^^^^^^^^^^^^^^^^^^^^^^^
  File "C:\americo\API\TaskGenie_flask\venv\Lib\site-packages\flask\app.py", line 919, in full_dispatch_request
    rv = self.handle_user_exception(e)
         ^^^^^^^^^^^^^^^^^^^^^^^^^^^^^
  File "C:\americo\API\TaskGenie_flask\venv\Lib\site-packages\flask\app.py", line 802, in handle_user_exception
    return self.handle_http_exception(e)
           ^^^^^^^^^^^^^^^^^^^^^^^^^^^^^
  File "C:\americo\API\TaskGenie_flask\venv\Lib\site-packages\flask\app.py", line 777, in handle_http_exception
    return self.ensure_sync(handler)(e)  # type: ignore[no-any-return]
           ^^^^^^^^^^^^^^^^^^^^^^^^^^^^
  File "C:\americo\API\TaskGenie_flask\app\__init__.py", line 83, in not_found
    return render_template("errores.html", mensaje="Página no encontrada"), 404
           ^^^^^^^^^^^^^^^^^^^^^^^^^^^^^^^^^^^^^^^^^^^^^^^^^^^^^^^^^^^^^^^
  File "C:\americo\API\TaskGenie_flask\venv\Lib\site-packages\flask\templating.py", line 150, in render_template
    return _render(app, template, context)
           ^^^^^^^^^^^^^^^^^^^^^^^^^^^^^^^
  File "C:\americo\API\TaskGenie_flask\venv\Lib\site-packages\flask\templating.py", line 127, in _render
    app.update_template_context(context)
  File "C:\americo\API\TaskGenie_flask\venv\Lib\site-packages\flask\app.py", line 530, in update_template_context
    context.update(self.ensure_sync(func)())
                   ^^^^^^^^^^^^^^^^^^^^^^^^
  File "C:\americo\API\TaskGenie_flask\venv\Lib\site-packages\flask_login\utils.py", line 405, in _user_context_processor
    return dict(current_user=_get_user())
                             ^^^^^^^^^^^
  File "C:\americo\API\TaskGenie_flask\venv\Lib\site-packages\flask_login\utils.py", line 370, in _get_user
    current_app.login_manager._load_user()
  File "C:\americo\API\TaskGenie_flask\venv\Lib\site-packages\flask_login\login_manager.py", line 347, in _load_user
    raise Exception(
Exception: Missing user_loader or request_loader. Refer to http://flask-login.readthedocs.io/#how-it-works for more info.
127.0.0.1 - - [13/Jun/2025 14:20:21] "GET /.well-known/appspecific/com.chrome.devtools.json HTTP/1.1" 500 -

error console
Failed to load resource: the server responded with a status of 500 (INTERNAL SERVER ERROR)
127.0.0.1/:1 
            
            
            Failed to load resource: the server responded with a status of 500 (INTERNAL SERVER ERROR)
[NEW] Explain Console errors by using Copilot in Edge: click
         
         to explain an error. 
        Learn more


error 
html
Internal Server Error
The server encountered an internal error and was unable to complete your request. Either the server is overloaded or there is an error in the application.